Workbook

Sheet 说明与规则总览
B2: 📋 家校沟通与合作 · 六维诊断与双维分类评估量表 V2.0
B3: 融合「教师独立评估（30题+常模）」与「六维诊断+双维分类」两套工具，单一填表、双视图结论
B5: 工具用途 | C5: 面向班主任/年级组，对单一学生家庭的“家校沟通与合作”状况进行结构化评估：既看健康水平（常模对照），也看病态风险（五级诊断），并做双维分类定位，支撑分级干预决策。
B6: 适用对象 | C6: 由 班主任 / 教师 独立填写，无需家长参与；用于评估单一学生家庭与学校的沟通合作状况。
B7: 填写步骤 | C7: ① 在「评估量表」按 1–5 给 30 题打分（下拉选择）；② 在「诊断与双维分类报告」选定双维分类代码（S/P/A-E）；③ 报告页自动生成均分、风险总分、干预级别与典型画像，对照「维度参考与规则速查」制定方案。
B8: 两套视图方向（重要） | C8: · 健康视图：量表 1–5 评分、维度均分、与常模差值 —— 数值越高=越健康越好。 · 风险视图：由均分自动换算的“风险等级(1–5)”、风险总分(6–30)、综合干预级别 —— 数值越高=问题越严重、风险越大。两者方向相反，请勿混淆。
B9: 结果查看 | C9: 「诊断与双维分类报告」页根据填写自动计算：维度均分、风险等级、等级描述、与常模差值、风险总分、综合干预级别、触发条件、建议动作、最薄弱维度、双维典型画像与核心策略。
B10: 保密要求 | C10: 评估数据仅用于内部管理，严格保密。
B12: 评分锚点（评估量表 1–5）
B13: 1 | C13: 非常不符合
B14: 2 | C14: 比较不符合
B15: 3 | C15: 一般 / 不确定
B16: 4 | C16: 比较符合
B17: 5 | C17: 非常符合
B19: 五级干预级别一览（风险总分 / 综合干预级别）
B20: 常态维持 | C20: 风险总分≤10 ｜ 触发：Y类 0项 ｜ 动作：常态观察与维持
B21: 1级 · 关注 | C21: 风险总分≤15 ｜ 触发：Y类 ≥1-2 ｜ 动作：班主任关注（基础预防）
B22: 2级 · 轻度 | C22: 风险总分≤20 ｜ 触发：O≥1 或 Y≥3-4 ｜ 动作：班主任+年级组（普及干预）
B23: 3级 · 中度 | C23: 风险总分≤25 ｜ 触发：O≥2 或 Y≥5 ｜ 动作：定向干预组（班主任+心理教师+年级主任）
B24: 4级 · 重度 | C24: 风险总分≤28 ｜ 触发：O≥3 ｜ 动作：强化干预组（心理团队+年级主任+管理层）
B25: 5级 · 极重 | C25: 风险总分≤30 ｜ 触发：R类任一命中 ｜ 动作：危机响应组（管理层+心理团队+外部专家）
B27: 六维名称
B28: 沟通质量 · 角色边界 · 教育一致性 · 信任关系 · 参与效能 · 危机响应（每维 5 题，共 30 题）

Sheet 评估量表
A1: 📋 六维评估量表（教师独立填写 · 唯一输入）
A2: 每题按 1（非常不符合）~ 5（非常符合）评分；共 6 维度 × 5 题 = 30 题。评分越高=家校关系越健康。
A4: 评估对象(学生/家长) | D4: 班主任
A5: 班级 | D5: 填写日期
A7: 1. 沟通质量（双向性/及时性） | D7: 常模参考均分 | E7: 4
A8: 1 | B8: 沟通质量 | C8: 我与这位家长能够顺畅、及时地交流孩子的在校情况
A9: 2 | B9: 沟通质量 | C9: 这位家长会主动向我反馈孩子在家中的表现与变化
A10: 3 | B10: 沟通质量 | C10: 我与这位家长沟通时氛围轻松，双方都能坦诚表达
A11: 4 | B11: 沟通质量 | C11: 这位家长能够清晰表达自己对教育的期望与诉求
A12: 5 | B12: 沟通质量 | C12: 当我有重要信息需要传达时，能够确保有效送达并得到确认
C13: 本维度均分 | D13: =ROUND(AVERAGE(D8:D12),1) -> #DIV/0!
C14: 与常模差值 | D14: =ROUND(D13-E7,1) -> #DIV/0!
A16: 2. 角色边界（职责清晰度） | D16: 常模参考均分 | E16: 4
A17: 6 | B17: 角色边界 | C17: 这位家长能在合适的时间联系我，不打扰我的休息与非工作时间
A18: 7 | B18: 角色边界 | C18: 这位家长尊重我在教学与班级事务上的专业主导权
A19: 8 | B19: 角色边界 | C19: 这位家长能把握参与的尺度，不过度介入班级内部事务
A20: 9 | B20: 角色边界 | C20: 这位家长与我的交往保持恰当的职业距离，不越界
A21: 10 | B21: 角色边界 | C21: 这位家长理解并配合学校在家长群、家委会等渠道上的规则
C22: 本维度均分 | D22: =ROUND(AVERAGE(D17:D21),1) -> #DIV/0!
C23: 与常模差值 | D23: =ROUND(D22-E16,1) -> #DIV/0!
A25: 3. 教育一致性（价值观/规则协调） | D25: 常模参考均分 | E25: 4
A26: 11 | B26: 教育一致性 | C26: 这位家长认同并接纳学校的教育理念与要求
A27: 12 | B27: 教育一致性 | C27: 这位家长尊重我的专业判断与教学决策
A28: 13 | B28: 教育一致性 | C28: 即使存在分歧，这位家长也能配合执行学校的统一安排
A29: 14 | B29: 教育一致性 | C29: 这位家长在孩子面前维护学校与教师的权威，不唱反调
A30: 15 | B30: 教育一致性 | C30: 这位家长在家庭教育中能与学校要求保持一致、形成合力
C31: 本维度均分 | D31: =ROUND(AVERAGE(D26:D30),1) -> #DIV/0!
C32: 与常模差值 | D32: =ROUND(D31-E25,1) -> #DIV/0!
A34: 4. 信任关系（尊重/心理安全感） | D34: 常模参考均分 | E34: 4
A35: 16 | B35: 信任关系 | C35: 我信任这位家长在孩子教育上的判断力
A36: 17 | B36: 信任关系 | C36: 我相信这位家长会履行与学校达成的约定
A37: 18 | B37: 信任关系 | C37: 我认为这位家长诚实可靠、言出必行
A38: 19 | B38: 信任关系 | C38: 即使有分歧，我仍相信这位家长的出发点是为孩子好
A39: 20 | B39: 信任关系 | C39: 我相信这位家长会优先把孩子利益放在首位
C40: 本维度均分 | D40: =ROUND(AVERAGE(D35:D39),1) -> #DIV/0!
C41: 与常模差值 | D41: =ROUND(D40-E34,1) -> #DIV/0!
A43: 5. 参与效能（实际效果与感知） | D43: 常模参考均分 | E43: 4
A44: 21 | B44: 参与效能 | C44: 当我提出建议时，这位家长会积极回应而非敷衍
A45: 22 | B45: 参与效能 | C45: 这位家长能将我的反馈转化为实际的教育行动
A46: 23 | B46: 参与效能 | C46: 孩子出现问题时，这位家长能及时配合解决
...

Sheet 诊断与双维分类报告
A1: 📊 诊断与双维分类报告（依据评估量表自动生成）
A2: 上半部：六维诊断（均分→风险等级→风险总分→干预级别）；下半部：双维分类定位
A4: 一、六维诊断（健康/风险双视图）
A6: 维度 | B6: 教师均分 | C6: 风险等级 | D6: 等级描述(由均分换算) | E6: 与常模差值 | F6: 维度干预级别
A7: 沟通质量 | B7: =评估量表!D13 -> #DIV/0! | C7: =IF(B7>=4,1,IF(B7>=3,2,IF(B7>=2,3,IF(B7>=1,4,5)))) -> #DIV/0! | D7: =INDEX('[1]#REF'!$B$5:$F$5,C7) -> #DIV/0! | E7: =ROUND(B7-评估量表!E7,1) -> #DIV/0! | F7: =IF(C7=1,"1级·关注",IF(C7=2,"2级·轻度",IF(C7=3,"3级·中度",IF(C7=4,"4级·重度","5级·极重")))) -> #DIV/0!
A8: 角色边界 | B8: =评估量表!D22 -> #DIV/0! | C8: =IF(B8>=4,1,IF(B8>=3,2,IF(B8>=2,3,IF(B8>=1,4,5)))) -> #DIV/0! | D8: =INDEX('[1]#REF'!$B$6:$F$6,C8) -> #DIV/0! | E8: =ROUND(B8-评估量表!E16,1) -> #DIV/0! | F8: =IF(C8=1,"1级·关注",IF(C8=2,"2级·轻度",IF(C8=3,"3级·中度",IF(C8=4,"4级·重度","5级·极重")))) -> #DIV/0!
A9: 教育一致性 | B9: =评估量表!D31 -> #DIV/0! | C9: =IF(B9>=4,1,IF(B9>=3,2,IF(B9>=2,3,IF(B9>=1,4,5)))) -> #DIV/0! | D9: =INDEX('[1]#REF'!$B$7:$F$7,C9) -> #DIV/0! | E9: =ROUND(B9-评估量表!E25,1) -> #DIV/0! | F9: =IF(C9=1,"1级·关注",IF(C9=2,"2级·轻度",IF(C9=3,"3级·中度",IF(C9=4,"4级·重度","5级·极重")))) -> #DIV/0!
A10: 信任关系 | B10: =评估量表!D40 -> #DIV/0! | C10: =IF(B10>=4,1,IF(B10>=3,2,IF(B10>=2,3,IF(B10>=1,4,5)))) -> #DIV/0! | D10: =INDEX('[1]#REF'!$B$8:$F$8,C10) -> #DIV/0! | E10: =ROUND(B10-评估量表!E34,1) -> #DIV/0! | F10: =IF(C10=1,"1级·关注",IF(C10=2,"2级·轻度",IF(C10=3,"3级·中度",IF(C10=4,"4级·重度","5级·极重")))) -> #DIV/0!
A11: 参与效能 | B11: =评估量表!D49 -> #DIV/0! | C11: =IF(B11>=4,1,IF(B11>=3,2,IF(B11>=2,3,IF(B11>=1,4,5)))) -> #DIV/0! | D11: =INDEX('[1]#REF'!$B$9:$F$9,C11) -> #DIV/0! | E11: =ROUND(B11-评估量表!E43,1) -> #DIV/0! | F11: =IF(C11=1,"1级·关注",IF(C11=2,"2级·轻度",IF(C11=3,"3级·中度",IF(C11=4,"4级·重度","5级·极重")))) -> #DIV/0!
A12: 危机响应 | B12: =评估量表!D58 -> #DIV/0! | C12: =IF(B12>=4,1,IF(B12>=3,2,IF(B12>=2,3,IF(B12>=1,4,5)))) -> #DIV/0! | D12: =INDEX('[1]#REF'!$B$10:$F$10,C12) -> #DIV/0! | E12: =ROUND(B12-评估量表!E52,1) -> #DIV/0! | F12: =IF(C12=1,"1级·关注",IF(C12=2,"2级·轻度",IF(C12=3,"3级·中度",IF(C12=4,"4级·重度","5级·极重")))) -> #DIV/0!
A14: 风险总分(6–30) | B14: =SUM(C7:C12) -> #DIV/0!
A15: 综合干预级别 | B15: =IF(SUM(C7:C12)<=10,"常态维持",IF(SUM(C7:C12)<=15,"1级·关注",IF(SUM(C7:C12)<=20,"2级·轻度",IF(SUM(C7:C12)<=25,"3级·中度",IF(SUM(C7:C12)<=28,"4级·重度","5级·极重"))))) -> #DIV/0!
A16: 触发条件 | B16: =IF(SUM(C7:C12)<=10,"Y类 0项",IF(SUM(C7:C12)<=15,"Y类 ≥1-2",IF(SUM(C7:C12)<=20,"O≥1 或 Y≥3-4",IF(SUM(C7:C12)<=25,"O≥2 或 Y≥5",IF(SUM(C7:C12)<=28,"O≥3","R类任一命中"))))) -> #DIV/0!
A17: 建议动作 | B17: =IF(SUM(C7:C12)<=10,"常态观察与维持",IF(SUM(C7:C12)<=15,"班主任关注（基础预防）",IF(SUM(C7:C12)<=20,"班主任+年级组（普及干预）",IF(SUM(C7:C12)<=25,"定向干预组（班主任+心理教师+年级主任）",IF(SUM(C7:C12)<=28,"强化干预组（心理团队+年级主任+管理层）","危机响应组（管理层+心理团队+外部专家）"))))) -> #DIV/0!
A19: 📌 核心干预建议 | B19: =INDEX(A7:A12,MATCH(MIN(B7:B12),B7:B12,0))&" （均分 "&ROUND(MIN(B7:B12),1)&"）" -> #DIV/0!
B20: =IF(SUM(C7:C12)<=10,"状态良好，保持常态沟通与观察；",IF(SUM(C7:C12)<=15,"存在轻度风险，建议班主任+年级组介入预防性干预；",IF(SUM(C7:C12)<=20,"存在中度偏差，需班主任+心理教师+年级主任定向干预；",IF(SUM(C7:C12)<=25,"存在重度风险，需心理团队+年级主任+管理层强化协作；",IF(SUM(C7:C12)<=28,"存在严重风险，需危机响应组紧急应对；","存在极端危机，需管理层+心理团队+外部专家立即响应；")))))&" 优先聚焦最薄弱维度「"&INDEX(A7:A12,MATCH(MIN(B7:B12),B7:B12,0))&"」，并参考「维度参考与规则速查」中的必要条件与分级描述制定方案。" -> #DIV/0!
A22: 二、双维分类评定（S型 × P型 × A-E级）
A23: 学生分类 (S型) | B23: S2 | C23: =VLOOKUP($B$23,$A$35:$B$40,2,FALSE) -> S2 稳定发展型
A24: 亲子关系 (P型) | B24: P2 | C24: =VLOOKUP($B$24,$A$42:$B$49,2,FALSE) -> P2 过度干预型
A25: 家校关系 (A-E级) | B25: C | C25: =VLOOKUP($B$25,$A$51:$B$55,2,FALSE) -> C 中性观望型
A26: P型基准 | B26: =IF(LEFT($B$24,2)="P1","P1",$B$24) -> P2
A28: 典型画像与核心策略 | B28: =IF(AND($B$25="E",OR($B$26="P3",$B$26="P5")),"负面干扰型 | 专项管控+法务介入+全程留痕（E级专项应对）",IF($B$25="E","负面干扰型（其他组合） | 按E级专项管控，德育处对接，班主任不单独应对",IF(AND(OR($B$23="S1",$B$23="S2"),OR($B$24="P1-A",$B$24="P1-C"),OR($B$25="A",$B$25="B")),"高知型/协同标杆 | 专业对话+理念交流+UPR引导（深度合作）",IF(AND(OR($B$23="S1",$B$23="S3"),OR($B$26="P2",$B$24="P1-B"),OR($B$25="C",$B$25="D")),"过度干预型 | 容器理论+替代参与+边界守护",IF(AND(OR($B$23="S3",$B$23="S4",$B$23="S5"),$B$26="P3",$B$25="C"),"缺位型 | 低门槛激活+容器修复+自我接纳",IF(AND(OR($B$23="S3",$B$23="S5"),$B$26="P4",$B$25="D"),"溺爱包庇型 | 明确规则+温和坚定+边界建立",IF(AND(OR($B$23="S4",$B$23="S5"),$B$26="P5",OR($B$25="D",$B$25="E")),"简单粗暴型 | 儿童保护+上报+停伤害+专业转介",IF(OR($B$25="A",$B$25="B"),"积极合作导向 | UPR巩固+深度合作/标杆引领",IF($B$25="C","中性观望/被动配合 | 加强沟通+唤醒关注+低门槛参与",IF($B$25="D","重点关注/潜在风险 | 专项沟通+防E转化+边界守护","待定组合 | 参照手册策略卡，结合容器状态与依恋模式定制")))))))))) -> 中性观望/被动配合 | 加强沟通+唤醒关注+低门槛参与
A33: （以下为双维分类选项对照表，仅供公式引用）
A34: 代码 | B34: 名称
A35: S1 | B35: S1 自主卓越型
A36: S2 | B36: S2 稳定发展型
A37: S3 | B37: S3 潜力未发型
A38: S4 | B38: S4 适应困难型
A39: S5 | B39: S5 高风险预警型
A40: S6 | B40: S6 危机紧急型
A41: 代码 | B41: 名称
A42: P1-A | B42: P1-A 协同·积极高效
A43: P1-B | B43: P1-B 协同·积极低效
A44: P1-C | B44: P1-C 协同·被动高效
A45: P1-D | B45: P1-D 协同·被动低效
... A55: E | B55: E 负面干扰型

Sheet 维度参考与规则速查
A1: 📖 维度参考与规则速查（融合 V2.0）
A3: 一、六维风险分级描述表（1级关注 → 5级极重；等级越高问题越严重）
A4: 维度 | B4: 1级(关注) | C4: 2级(轻度) | D4: 3级(中度) | E4: 4级(重度) | F4: 5级(极重)
A5: 沟通质量 | B5: 偶尔不畅，可补位 | C5: 系统性单向，反馈受限 | D5: 长期单向，误解频繁 | E5: 严重障碍，多渠道失效 | F5: 完全断裂，无法触及
A6: 角色边界 | B6: 偶有模糊，可协商 | C6: 越界初现，试探替代 | D6: 越界/缺位反复出现 | E6: 严重错乱，持续替代 | F6: 完全崩塌，强行取代
A7: 教育一致性 | B7: 偶有分歧，可化解 | C7: 规则偶尔矛盾，可协商 | D7: 规则矛盾，学生两面性 | E7: 理念深层冲突，公开否定 | F7: 理念根本对立，对抗阵营
A8: 信任关系 | B8: 偶尔猜疑，合作未受影响 | C8: 选择性信任，部分存疑 | D8: 经常私下求证，基础动摇 | E8: 信任崩塌，预设恶意 | F8: 完全丧失，敌意常态化
A9: 参与效能 | B9: 不充分但态度积极 | C9: 形式化，效果有限 | D9: 无效或偏离目标 | E9: 产生负效应，干扰教育 | F9: 完全退出或恶意破坏
A10: 危机响应 | B10: 偶有不当，可修正 | C10: 响应滞后 24-48h | D10: 机制缺失，延误 >48h | E10: 一方利用攻击另一方 | F10: 对抗升级，安全风险显现
A12: 二、风险等级换算规则（评估量表维度均分 → 风险等级）
A13: 均分区间 | B13: 风险等级 | C13: 含义
A14: ≥ 4.0 | B14: 1级 | C14: 健康/低风险
A15: 3.0 – 3.9 | B15: 2级 | C15: 轻度风险·关注
A16: 2.0 – 2.9 | B16: 3级 | C16: 中度风险
A17: 1.0 – 1.9 | B17: 4级 | C17: 重度风险
A18: < 1.0 | B18: 5级 | C18: 极重风险
A20: 三、风险总分判定决策树（六维风险等级合计 6–30）
A21: 总分区间 | B21: 干预级别 | C21: 触发条件 | D21: 建议动作
A22: 6–10 | B22: 常态维持 | C22: Y类 0项 | D22: 常态观察与维持
A23: 11–15 | B23: 1级 · 关注 | C23: Y类 ≥1-2 | D23: 班主任关注（基础预防）
A24: 16–20 | B24: 2级 · 轻度 | C24: O≥1 或 Y≥3-4 | D24: 班主任+年级组（普及干预）
A25: 21–25 | B25: 3级 · 中度 | C25: O≥2 或 Y≥5 | D25: 定向干预组（班主任+心理教师+年级主任）
A26: 26–28 | B26: 4级 · 重度 | C26: O≥3 | D26: 强化干预组（心理团队+年级主任+管理层）
A27: 29–30 | B27: 5级 · 极重 | C27: R类任一命中 | D27: 危机响应组（管理层+心理团队+外部专家）
A29: 四、双维分类选项
A30: 学生分类(S型) | B30: S1 自主卓越型；S2 稳定发展型；S3 潜力未发型；S4 适应困难型；S5 高风险预警型；S6 危机紧急型
A31: 亲子关系(P型) | B31: P1-A 协同·积极高效；P1-B 协同·积极低效；P1-C 协同·被动高效；P1-D 协同·被动低效；P2 过度干预型；P3 缺位型；P4 溺爱包庇型；P5 简单粗暴型
A32: 家校关系(A-E级) | B32: A 核心标杆型；B 积极配合型；C 中性观望型；D 重点关注型；E 负面干扰型
A34: 五、双维交叉定位逻辑（以家校关系为枢纽，基于手册4.4）
A35: 1 | B35: 家校关系=E 且 (P3缺位 / P5简单粗暴)：负面干扰型 → 专项管控+法务介入+全程留痕（E级专项）
A36: 2 | B36: 家校关系=E（其他组合）：负面干扰型 → 按E级专项管控，德育处对接，班主任不单独应对
A37: 3 | B37: S1/S2 且 (P1-A/P1-C) 且 A/B：高知型/协同标杆 → 专业对话+理念交流+UPR引导
A38: 4 | B38: S1/S3 且 (P2过度干预 / P1-B) 且 C/D：过度干预型 → 容器理论+替代参与+边界守护
A39: 5 | B39: S3/S4/S5 且 P3缺位 且 C：缺位型 → 低门槛激活+容器修复+自我接纳
A40: 6 | B40: S3/S5 且 P4溺爱包庇 且 D：溺爱包庇型 → 明确规则+温和坚定+边界建立
A41: 7 | B41: S4/S5 且 P5简单粗暴 且 D/E：简单粗暴型 → 儿童保护+上报+停伤害+专业转介
A42: 8 | B42: 兜底（按家校关系）：A/B→积极合作导向；C→中性观望/被动配合；D→重点关注/潜在风险；其余→待定组合
A44: 六、维度参考：常模说明 · 典型问题 · 必要条件
A45: 维度 | B45: 常模参考说明 | C45: 典型问题（维度偏低时表现） | D45: 必要条件（健康的前提）
A46: 沟通质量 | B46: 常模参考均分 4.0（满分5） 代表健康基线，可由学校依历年数据或区域常模校准；均分≥常模为正常，明显低于常模需关注。 | C46: • 信息传递滞后或失真，重要事项无法及时触达家长 • 家长被动等待通知，缺乏主动反馈，教师难掌握家庭端情况 • 沟通氛围紧张，双方回避或防御性表达，问题被掩盖 | D46: • 建立稳定、固定的沟通渠道与联系节奏（如每周反馈机制） • 教师主动发起正向沟通，积累信任后再谈问题 • 明确重要信息的送达与确认流程（如回执/已读确认）
...
